<?xml version="1.0" encoding="utf-8"?>
<mujoco model="g1_29dof_rev_1_0">
  <compiler angle="radian" autolimits="true"/>
  <default>
    <joint damping="0.001" armature="0.01" frictionloss="0.1"/>
  </default>
  <asset>
    <mesh name="pelvis" file="pelvis.STL"/>
    <mesh name="pelvis_contour_link" file="pelvis_contour_link.STL"/>
    <mesh name="left_hip_pitch_link" file="left_hip_pitch_link.STL"/>
    <mesh name="left_hip_roll_link" file="left_hip_roll_link.STL"/>
    <mesh name="left_hip_yaw_link" file="left_hip_yaw_link.STL"/>
    <mesh name="left_knee_link" file="left_knee_link.STL"/>
    <mesh name="left_ankle_pitch_link" file="left_ankle_pitch_link.STL"/>
    <mesh name="left_ankle_roll_link" file="left_ankle_roll_link.STL"/>
    <mesh name="right_hip_pitch_link" file="right_hip_pitch_link.STL"/>
    <mesh name="right_hip_roll_link" file="right_hip_roll_link.STL"/>
    <mesh name="right_hip_yaw_link" file="right_hip_yaw_link.STL"/>
    <mesh name="right_knee_link" file="right_knee_link.STL"/>
    <mesh name="right_ankle_pitch_link" file="right_ankle_pitch_link.STL"/>
    <mesh name="right_ankle_roll_link" file="right_ankle_roll_link.STL"/>
    <mesh name="waist_yaw_link_rev_1_0" file="waist_yaw_link_rev_1_0.STL"/>
    <mesh name="waist_roll_link_rev_1_0" file="waist_roll_link_rev_1_0.STL"/>
    <mesh name="torso_link_rev_1_0" file="torso_link_rev_1_0.STL"/>
    <mesh name="logo_link" file="logo_link.STL"/>
    <mesh name="head_link" file="head_link.STL"/>
    <mesh name="left_shoulder_pitch_link" file="left_shoulder_pitch_link.STL"/>
    <mesh name="left_shoulder_roll_link" file="left_shoulder_roll_link.STL"/>
    <mesh name="left_shoulder_yaw_link" file="left_shoulder_yaw_link.STL"/>
    <mesh name="left_elbow_link" file="left_elbow_link.STL"/>
    <mesh name="left_wrist_roll_link" file="left_wrist_roll_link.STL"/>
    <mesh name="left_wrist_pitch_link" file="left_wrist_pitch_link.STL"/>
    <mesh name="left_wrist_yaw_link" file="left_wrist_yaw_link.STL"/>
    <mesh name="left_rubber_hand" file="left_rubber_hand.STL"/>
    <mesh name="right_shoulder_pitch_link" file="right_shoulder_pitch_link.STL"/>
    <mesh name="right_shoulder_roll_link" file="right_shoulder_roll_link.STL"/>
    <mesh name="right_shoulder_yaw_link" file="right_shoulder_yaw_link.STL"/>
    <mesh name="right_elbow_link" file="right_elbow_link.STL"/>
    <mesh name="right_wrist_roll_link" file="right_wrist_roll_link.STL"/>
    <mesh name="right_wrist_pitch_link" file="right_wrist_pitch_link.STL"/>
    <mesh name="right_wrist_yaw_link" file="right_wrist_yaw_link.STL"/>
    <mesh name="right_rubber_hand" file="right_rubber_hand.STL"/>
  </asset>
  <worldbody>
    <body name="base_link" pos="0 0 0.9">
      <joint name="base_link_free_joint" type="free" limited="false"/>
      <geom type="mesh" contype="0" conaffinity="0" group="1" density="0" rgba="0.2 0.2 0.2 1" mesh="pelvis"/>
      <geom type="mesh" contype="0" conaffinity="0" group="1" density="0" rgba="0.7 0.7 0.7 1" mesh="pelvis_contour_link"/>
      <!-- <geom type="mesh" rgba="0.7 0.7 0.7 1" mesh="pelvis_contour_link"/> -->
      <!-- pelvis collision -->
      <geom name="pelvis_collision" type="sphere" size="0.07" pos="0 0 -0.08" contype="1" conaffinity="1" rgba="0 0 0 0"/>
      <body name="leg_l1_link" pos="0 0.064452 -0.1027" gravcomp="0">
        <inertial pos="0.002741 0.047791 -0.02606" quat="0.954862 0.293964 0.0302556 0.030122" mass="1.35" diaginertia="0.00181517 0.00153422 0.00116212"/>
        <joint name="leg_l1_joint" pos="0 0 0" axis="0 1 0" range="-2.5307 2.8798"/>
        <!-- <joint name="leg_l1_joint" pos="0 0 0" axis="0 1 0" range="-6.5307 6.8798"/> -->
        <geom type="mesh" contype="0" conaffinity="0" group="1" density="0" rgba="0.2 0.2 0.2 1" mesh="left_hip_pitch_link"/>
        <body name="leg_l2_link" pos="0 0.052 -0.030465" quat="0.996179 0 -0.0873386 0" gravcomp="0">
          <inertial pos="0.029812 -0.001045 -0.087934" quat="0.977808 -1.97119e-05 0.205576 -0.0403793" mass="1.52" diaginertia="0.00254986 0.00241169 0.00148755"/>
          <joint name="leg_l2_joint" pos="0 0 0" axis="1 0 0" range="-0.5236 2.9671"/>
          <!-- <joint name="leg_l2_joint" pos="0 0 0" axis="1 0 0" range="-6.5236 6.9671"/> -->
          <geom type="mesh" contype="0" conaffinity="0" group="1" density="0" rgba="0.7 0.7 0.7 1" mesh="left_hip_roll_link"/>
          <!-- left thigh collision -->
          <geom name="left_thigh" type="capsule" size="0.05" fromto="0.02 0 0 0.02 0 -0.2" contype="1" conaffinity="1" rgba="0 0 0 0"/>
          <body name="leg_l3_link" pos="0.025001 0 -0.12412" gravcomp="0">
            <inertial pos="-0.057709 -0.010981 -0.15078" quat="0.600598 0.15832 0.223482 0.751181" mass="1.702" diaginertia="0.00776166 0.00717575 0.00160139"/>
            <joint name="leg_l3_joint" pos="0 0 0" axis="0 0 1" range="-2.7576 2.7576"/>
            <!-- <joint name="leg_l3_joint" pos="0 0 0" axis="0 0 1" range="-6.7576 6.7576"/> -->
            <geom type="mesh" contype="0" conaffinity="0" group="1" density="0" rgba="0.7 0.7 0.7 1" mesh="left_hip_yaw_link"/>
            <body name="leg_l4_link_knee" pos="-0.078273 0.0021489 -0.17734" quat="0.996179 0 0.0873386 0" gravcomp="0">
              <inertial pos="0.005457 0.003964 -0.12074" quat="0.923418 -0.0327699 0.0158246 0.382067" mass="1.932" diaginertia="0.0113804 0.0112778 0.00146458"/>
              <joint name="leg_l4_joint" pos="0 0 0" axis="0 1 0" range="-0.087267 2.8798"/>
              <!-- <joint name="leg_l4_joint" pos="0 0 0" axis="0 1 0" range="-6.087267 6.8798"/> -->
              <geom type="mesh" contype="0" conaffinity="0" group="1" density="0" rgba="0.7 0.7 0.7 1" mesh="left_knee_link"/>
              <!-- left shin collision -->
              <geom name="left_shin" type="capsule" size="0.04" fromto="0.02 0 0 0.02 0 -0.25" contype="1" conaffinity="1" rgba="0 0 0 0"/>
              <body name="leg_l5_link" pos="0 -9.4445e-05 -0.30001" gravcomp="0">
                <inertial pos="-0.007269 0 0.011137" quat="0.603053 0.369225 0.369225 0.603053" mass="0.074" diaginertia="1.89e-05 1.40805e-05 6.9195e-06"/>
                <joint name="leg_l5_joint" pos="0 0 0" axis="0 1 0" range="-0.87267 0.5236"/>
                <!-- <joint name="leg_l5_joint" pos="0 0 0" axis="0 1 0" range="-6.87267 6.5236"/>   -->
                <geom type="mesh" contype="0" conaffinity="0" group="1" density="0" rgba="0.7 0.7 0.7 1" mesh="left_ankle_pitch_link"/>
                <body name="leg_l6_link" pos="0 0 -0.017558" gravcomp="0">
                  <inertial pos="0.026505 0 -0.016425" quat="-0.000481092 0.728482 -0.000618967 0.685065" mass="0.608" diaginertia="0.00167218 0.0016161 0.000217621"/>
                  <joint name="leg_l6_joint" pos="0 0 0" axis="1 0 0" range="-0.2618 0.2618"/>
                  <!-- <joint name="leg_l6_joint" pos="0 0 0" axis="1 0 0" range="-6.2618 6.2618"/> -->
                  <geom type="mesh" contype="0" conaffinity="0" group="1" density="0" rgba="0.2 0.2 0.2 1" mesh="left_ankle_roll_link"/>
                  <!-- left foot collision capsules -->
                  <geom name="left_foot1_collision" type="capsule" size="0.01" fromto="0.1 -0.026 -0.025 0.05 -0.027 -0.025" contype="1" conaffinity="1" rgba="0 0 0 0"/>
                  <geom name="left_foot2_collision" type="capsule" size="0.01" fromto="-0.044 -0.018 -0.025 0.123 -0.018 -0.025" contype="1" conaffinity="1" rgba="0 0 0 0"/>
                  <geom name="left_foot3_collision" type="capsule" size="0.01" fromto="-0.052 -0.01 -0.025 0.13 -0.01 -0.025" contype="1" conaffinity="1" rgba="0 0 0 0"/>
                  <geom name="left_foot4_collision" type="capsule" size="0.01" fromto="-0.054 0 -0.025 0.132 0 -0.025" contype="1" conaffinity="1" rgba="0 0 0 0"/>
                  <geom name="left_foot5_collision" type="capsule" size="0.01" fromto="-0.052 0.01 -0.025 0.13 0.01 -0.025" contype="1" conaffinity="1" rgba="0 0 0 0"/>
                  <geom name="left_foot6_collision" type="capsule" size="0.01" fromto="-0.044 0.018 -0.025 0.123 0.018 -0.025" contype="1" conaffinity="1" rgba="0 0 0 0"/>
                  <geom name="left_foot7_collision" type="capsule" size="0.01" fromto="0.1 0.026 -0.025 0.05 0.026 -0.025" contype="1" conaffinity="1" rgba="0 0 0 0"/>
                </body>
              </body>
            </body>
          </body>
        </body>
      </body>
      <body name="leg_r1_link" pos="0 -0.064452 -0.1027" gravcomp="0">
        <inertial pos="0.002741 -0.047791 -0.02606" quat="0.954862 -0.293964 0.0302556 -0.030122" mass="1.35" diaginertia="0.00181517 0.00153422 0.00116212"/>
        <joint name="leg_r1_joint" pos="0 0 0" axis="0 1 0" range="-2.5307 2.8798"/>
        <!-- <joint name="leg_r1_joint" pos="0 0 0" axis="0 1 0" range="-6.5307 6.8798"/> -->
        <geom type="mesh" contype="0" conaffinity="0" group="1" density="0" rgba="0.2 0.2 0.2 1" mesh="right_hip_pitch_link"/>
        <body name="leg_r2_link" pos="0 -0.052 -0.030465" quat="0.996179 0 -0.0873386 0" gravcomp="0">
          <inertial pos="0.029812 0.001045 -0.087934" quat="0.977808 1.97119e-05 0.205576 0.0403793" mass="1.52" diaginertia="0.00254986 0.00241169 0.00148755"/>
          <joint name="leg_r2_joint" pos="0 0 0" axis="1 0 0" range="-2.9671 0.5236"/>
          <!-- <joint name="leg_r2_joint" pos="0 0 0" axis="1 0 0" range="-6.9671 6.5236"/> -->
          <geom type="mesh" contype="0" conaffinity="0" group="1" density="0" rgba="0.7 0.7 0.7 1" mesh="right_hip_roll_link"/>
          <!-- right thigh collision -->
          <geom name="right_thigh" type="capsule" size="0.05" fromto="0.02 0 0 0.02 0 -0.2" contype="1" conaffinity="1" rgba="0 0 0 0"/>
          <body name="leg_r3_link" pos="0.025001 0 -0.12412" gravcomp="0">
            <inertial pos="-0.057709 0.010981 -0.15078" quat="0.751181 0.223482 0.15832 0.600598" mass="1.702" diaginertia="0.00776166 0.00717575 0.00160139"/>
            <joint name="leg_r3_joint" pos="0 0 0" axis="0 0 1" range="-2.7576 2.7576"/>
            <!-- <joint name="leg_r3_joint" pos="0 0 0" axis="0 0 1" range="-6.7576 6.7576"/> -->
            <geom type="mesh" contype="0" conaffinity="0" group="1" density="0" rgba="0.7 0.7 0.7 1" mesh="right_hip_yaw_link"/>
            <body name="leg_r4_link_knee" pos="-0.078273 -0.0021489 -0.17734" quat="0.996179 0 0.0873386 0" gravcomp="0">
              <inertial pos="0.005457 -0.003964 -0.12074" quat="0.923439 0.0345276 0.0116333 -0.382012" mass="1.932" diaginertia="0.011374 0.0112843 0.00146452"/>
              <joint name="leg_r4_joint" pos="0 0 0" axis="0 1 0" range="-0.087267 2.8798"/>
              <!-- <joint name="leg_r4_joint" pos="0 0 0" axis="0 1 0" range="-6.087267 6.8798"/> -->
              <geom type="mesh" contype="0" conaffinity="0" group="1" density="0" rgba="0.7 0.7 0.7 1" mesh="right_knee_link"/>
              <!-- right shin collision -->
              <geom name="right_shin" type="capsule" size="0.04" fromto="0.02 0 0 0.02 0 -0.25" contype="1" conaffinity="1" rgba="0 0 0 0"/>
              <body name="leg_r5_link" pos="0 9.4445e-05 -0.30001" gravcomp="0">
                <inertial pos="-0.007269 0 0.011137" quat="0.603053 0.369225 0.369225 0.603053" mass="0.074" diaginertia="1.89e-05 1.40805e-05 6.9195e-06"/>
                <joint name="leg_r5_joint" pos="0 0 0" axis="0 1 0" range="-0.87267 0.5236"/>
                <!-- <joint name="leg_r5_joint" pos="0 0 0" axis="0 1 0" range="-6.87267 6.5236"/> -->
                <geom type="mesh" contype="0" conaffinity="0" group="1" density="0" rgba="0.7 0.7 0.7 1" mesh="right_ankle_pitch_link"/>
                <body name="leg_r6_link" pos="0 0 -0.017558" gravcomp="0">
                  <inertial pos="0.026505 0 -0.016425" quat="0.000481092 0.728482 0.000618967 0.685065" mass="0.608" diaginertia="0.00167218 0.0016161 0.000217621"/>
                    <joint name="leg_r6_joint" pos="0 0 0" axis="1 0 0" range="-0.2618 0.2618"/>
                  <!-- <joint name="leg_r6_joint" pos="0 0 0" axis="1 0 0" range="-6.2618 6.2618"/> -->
                  <geom type="mesh" contype="0" conaffinity="0" group="1" density="0" rgba="0.2 0.2 0.2 1" mesh="right_ankle_roll_link"/>
                  <!-- right foot collision capsules -->
                  <geom name="right_foot1_collision" type="capsule" size="0.01" fromto="0.1 -0.026 -0.025 0.05 -0.026 -0.025" contype="1" conaffinity="1" rgba="0 0 0 0"/>
                  <geom name="right_foot2_collision" type="capsule" size="0.008" fromto="-0.044 -0.018 -0.025 0.123 -0.018 -0.025" contype="1" conaffinity="1" rgba="0 0 0 0"/>
                  <geom name="right_foot3_collision" type="capsule" size="0.01" fromto="-0.052 -0.01 -0.025 0.13 -0.01 -0.025" contype="1" conaffinity="1" rgba="0 0 0 0"/>
                  <geom name="right_foot4_collision" type="capsule" size="0.01" fromto="-0.054 0 -0.025 0.132 0 -0.025" contype="1" conaffinity="1" rgba="0 0 0 0"/>
                  <geom name="right_foot5_collision" type="capsule" size="0.01" fromto="-0.052 0.01 -0.025 0.13 0.01 -0.025" contype="1" conaffinity="1" rgba="0 0 0 0"/>
                  <geom name="right_foot6_collision" type="capsule" size="0.008" fromto="-0.044 0.018 -0.025 0.123 0.018 -0.025" contype="1" conaffinity="1" rgba="0 0 0 0"/>
                  <geom name="right_foot7_collision" type="capsule" size="0.01" fromto="0.1 0.026 -0.025 0.05 0.026 -0.025" contype="1" conaffinity="1" rgba="0 0 0 0"/>
                </body>
              </body>
            </body>
          </body>
        </body>
      </body>
      <body name="waist_yaw_link" pos="0 0 0" gravcomp="0">
        <inertial pos="0.003494 0.000233 0.018034" quat="0.289697 0.591001 -0.337795 0.672821" mass="0.214" diaginertia="0.000163531 0.000107714 0.000102205"/>
        <joint name="waist_yaw_joint" pos="0 0 0" axis="0 0 1" range="-2.618 2.618"/>
        <geom type="mesh" contype="0" conaffinity="0" group="1" density="0" rgba="0.7 0.7 0.7 1" mesh="waist_yaw_link_rev_1_0"/>
        <body name="waist_roll_link" pos="-0.0039635 0 0.044" gravcomp="0">
          <inertial pos="0 2.3e-05 0" quat="0.5 0.5 -0.5 0.5" mass="0.086" diaginertia="8.245e-06 7.079e-06 6.339e-06"/>
          <joint name="waist_roll_joint" pos="0 0 0" axis="1 0 0" range="-0.52 0.52"/>
          <geom type="mesh" contype="0" conaffinity="0" group="1" density="0" rgba="0.7 0.7 0.7 1" mesh="waist_roll_link_rev_1_0"/>
          <body name="torso_link" pos="0 0 0" gravcomp="0">
            <inertial pos="0.00203133 0.000339727 0.184597" quat="0.999802 -5.98967e-05 0.0198391 0.0013197" mass="7.817" diaginertia="0.121795 0.109773 0.0273733"/>
            <joint name="waist_pitch_joint" pos="0 0 0" axis="0 1 0" range="-0.52 0.52"/>
            <geom type="mesh" contype="0" conaffinity="0" group="1" density="0" rgba="0.7 0.7 0.7 1" mesh="torso_link_rev_1_0"/>
            <geom pos="0.0039635 0 -0.044" type="mesh" contype="0" conaffinity="0" group="1" density="0" rgba="0.2 0.2 0.2 1" mesh="logo_link"/>
            <geom pos="0.0039635 0 -0.044" type="mesh" contype="0" conaffinity="0" group="1" density="0" rgba="0.2 0.2 0.2 1" mesh="head_link"/>
            <!-- torso and head collision capsules -->
            <geom name="torso_collision1" type="capsule" size="0.073" fromto="0.005 -0.032 .22 0.005 0.032 .22" contype="1" conaffinity="1" rgba="0 0 0 0"/>
            <geom name="torso_collision2" type="capsule" size="0.07" fromto="0.005 -0.028 .13 0.005 0.028 .13" contype="1" conaffinity="1" rgba="0 0 0 0"/>
            <geom name="torso_collision3" type="capsule" size="0.065" fromto="0.005 -0.02 .06 0.005 0.02 .06" contype="1" conaffinity="1" rgba="0 0 0 0"/>
            <geom name="head_collision" type="capsule" size="0.068" fromto="0.01 0 .41 0.01 0 .42" contype="1" conaffinity="1" rgba="0 0 0 0"/>
            <body name="arm_l1_link" pos="0.0039563 0.10022 0.24778" quat="0.990264 0.139201 1.38722e-05 -9.86868e-05" gravcomp="0">
              <inertial pos="0 0.035892 -0.011628" quat="0.654152 0.0130458 -0.326267 0.68225" mass="0.718" diaginertia="0.000465864 0.000432842 0.000406394"/>
              <joint name="arm_l1_joint" pos="0 0 0" axis="0 1 0" range="-3.0892 2.6704"/>
              <geom type="mesh" contype="0" conaffinity="0" group="1" density="0" rgba="0.7 0.7 0.7 1" mesh="left_shoulder_pitch_link"/>
              <body name="arm_l2_link" pos="0 0.038 -0.013831" quat="0.990268 -0.139172 0 0" gravcomp="0">
                <inertial pos="-0.000227 0.00727 -0.063243" quat="0.701256 -0.0196223 -0.00710317 0.712604" mass="0.643" diaginertia="0.000691311 0.000618011 0.000388977"/>
                <joint name="arm_l2_joint" pos="0 0 0" axis="1 0 0" range="-1.5882 2.2515"/>
                <geom type="mesh" contype="0" conaffinity="0" group="1" density="0" rgba="0.7 0.7 0.7 1" mesh="left_shoulder_roll_link"/>
                <body name="arm_l3_link" pos="0 0.00624 -0.1032" gravcomp="0">
                  <inertial pos="0.010773 -0.002949 -0.072009" quat="0.716879 -0.0964829 -0.0679942 0.687134" mass="0.734" diaginertia="0.00106187 0.00103217 0.000400661"/>
                  <joint name="arm_l3_joint" pos="0 0 0" axis="0 0 1" range="-2.618 2.618"/>
                  <geom type="mesh" contype="0" conaffinity="0" group="1" density="0" rgba="0.7 0.7 0.7 1" mesh="left_shoulder_yaw_link"/>
                  <!-- left shoulder yaw collision -->
                  <geom name="left_shoulder_yaw_collision" type="capsule" size="0.035" fromto="0 0 -0.08 0 0 0.05" contype="1" conaffinity="1" rgba="0 0 0 0"/>
                  <body name="arm_l4_link" pos="0.015783 0 -0.080518" gravcomp="0">
                    <inertial pos="0.064956 0.004454 -0.010062" quat="0.541765 0.636132 0.388821 0.388129" mass="0.6" diaginertia="0.000443035 0.000421612 0.000259353"/>
                    <joint name="arm_l4_joint" pos="0 0 0" axis="0 1 0" range="-1.0472 2.0944"/>
                    <geom type="mesh" contype="0" conaffinity="0" group="1" density="0" rgba="0.7 0.7 0.7 1" mesh="left_elbow_link"/>
                    <!-- left elbow collision -->
                    <geom name="left_elbow_yaw_collision" type="capsule" size="0.035" fromto="-0.01 0 -0.01 0.12 0 -0.01" contype="1" conaffinity="1" rgba="0 0 0 0"/>
                    <body name="arm_l5_link" pos="0.1 0.00188791 -0.01" gravcomp="0">
                      <inertial pos="0.0171394 0.000537591 4.8864e-07" quat="0.575338 0.411667 -0.574906 0.411094" mass="0.085445" diaginertia="5.48211e-05 4.96646e-05 3.57798e-05"/>
                      <joint name="arm_l5_joint" pos="0 0 0" axis="1 0 0" range="-1.97222 1.97222"/>
                      <geom type="mesh" contype="0" conaffinity="0" group="1" density="0" rgba="0.7 0.7 0.7 1" mesh="left_wrist_roll_link"/>
                      <body name="arm_l6_link" pos="0.038 0 0" gravcomp="0">
                        <inertial pos="0.0229999 -0.00111685 -0.00111658" quat="0.249998 0.661363 0.293036 0.643608" mass="0.48405" diaginertia="0.000430353 0.000429873 0.000164648"/>
                        <joint name="arm_l6_joint" pos="0 0 0" axis="0 1 0" range="-1.61443 1.61443"/>
                        <geom type="mesh" contype="0" conaffinity="0" group="1" density="0" rgba="0.7 0.7 0.7 1" mesh="left_wrist_pitch_link"/>
                        <body name="arm_l7_link" pos="0.046 0 0" gravcomp="0">
                          <inertial pos="0.0708244 0.000191745 0.00161742" quat="0.510571 0.526295 0.468078 0.493188" mass="0.254576" diaginertia="0.000646113 0.000559993 0.000147566"/>
                          <joint name="arm_l7_joint" pos="0 0 0" axis="0 0 1" range="-1.61443 1.61443"/>
                          <geom type="mesh" contype="0" conaffinity="0" group="1" density="0" rgba="0.7 0.7 0.7 1" mesh="left_wrist_yaw_link"/>
                          <geom pos="0.0415 0.003 0" type="mesh" contype="0" conaffinity="0" group="1" density="0" rgba="0.7 0.7 0.7 1" mesh="left_rubber_hand"/>
                          <!-- left hand collision -->
                          <geom name="left_hand_collision" type="capsule" size="0.05" fromto="0.05 0 0 0.1 0 0" contype="1" conaffinity="1" rgba="0 0 0 0"/>
                        </body>
                      </body>
                    </body>
                  </body>
                </body>
              </body>
            </body>
            <body name="arm_r1_link" pos="0.0039563 -0.10021 0.24778" quat="0.990264 -0.139201 1.38722e-05 9.86868e-05" gravcomp="0">
              <inertial pos="0 -0.035892 -0.011628" quat="0.68225 -0.326267 0.0130458 0.654152" mass="0.718" diaginertia="0.000465864 0.000432842 0.000406394"/>
              <joint name="arm_r1_joint" pos="0 0 0" axis="0 1 0" range="-3.0892 2.6704"/>
              <geom type="mesh" contype="0" conaffinity="0" group="1" density="0" rgba="0.7 0.7 0.7 1" mesh="right_shoulder_pitch_link"/>
              <body name="arm_r2_link" pos="0 -0.038 -0.013831" quat="0.990268 0.139172 0 0" gravcomp="0">
                <inertial pos="-0.000227 -0.00727 -0.063243" quat="0.712604 -0.00710317 -0.0196223 0.701256" mass="0.643" diaginertia="0.000691311 0.000618011 0.000388977"/>
                <joint name="arm_r2_joint" pos="0 0 0" axis="1 0 0" range="-2.2515 1.5882"/>
                <geom type="mesh" contype="0" conaffinity="0" group="1" density="0" rgba="0.7 0.7 0.7 1" mesh="right_shoulder_roll_link"/>
                <body name="arm_r3_link" pos="0 -0.00624 -0.1032" gravcomp="0">
                  <inertial pos="0.010773 0.002949 -0.072009" quat="0.687134 -0.0679942 -0.0964829 0.716879" mass="0.734" diaginertia="0.00106187 0.00103217 0.000400661"/>
                  <joint name="arm_r3_joint" pos="0 0 0" axis="0 0 1" range="-2.618 2.618"/>
                  <geom type="mesh" contype="0" conaffinity="0" group="1" density="0" rgba="0.7 0.7 0.7 1" mesh="right_shoulder_yaw_link"/>
                  <!-- right shoulder yaw collision -->
                  <geom name="right_shoulder_yaw_collision" type="capsule" size="0.035" fromto="0 0 -0.08 0 0 0.05" contype="1" conaffinity="1" rgba="0 0 0 0"/>
                  <body name="arm_r4_link" pos="0.015783 0 -0.080518" gravcomp="0">
                    <inertial pos="0.064956 -0.004454 -0.010062" quat="0.388129 0.388821 0.636132 0.541765" mass="0.6" diaginertia="0.000443035 0.000421612 0.000259353"/>
                    <joint name="arm_r4_joint" pos="0 0 0" axis="0 1 0" range="-1.0472 2.0944"/>
                    <geom type="mesh" contype="0" conaffinity="0" group="1" density="0" rgba="0.7 0.7 0.7 1" mesh="right_elbow_link"/>
                    <!-- right elbow collision -->
                    <geom name="right_elbow_yaw_collision" type="capsule" size="0.035" fromto="-0.01 0 -0.01 0.12 0 -0.01" contype="1" conaffinity="1" rgba="0 0 0 0"/>
                    <body name="arm_r5_link" pos="0.1 -0.00188791 -0.01" gravcomp="0">
                      <inertial pos="0.0171394 -0.000537591 4.8864e-07" quat="0.411667 0.575338 -0.411094 0.574906" mass="0.085445" diaginertia="5.48211e-05 4.96646e-05 3.57798e-05"/>
                      <joint name="arm_r5_joint" pos="0 0 0" axis="1 0 0" range="-1.97222 1.97222"/>
                      <geom type="mesh" contype="0" conaffinity="0" group="1" density="0" rgba="0.7 0.7 0.7 1" mesh="right_wrist_roll_link"/>
                      <body name="arm_r6_link" pos="0.038 0 0" gravcomp="0">
                        <inertial pos="0.0229999 0.00111685 -0.00111658" quat="0.643608 0.293036 0.661363 0.249998" mass="0.48405" diaginertia="0.000430353 0.000429873 0.000164648"/>
                        <joint name="arm_r6_joint" pos="0 0 0" axis="0 1 0" range="-1.61443 1.61443"/>
                        <geom type="mesh" contype="0" conaffinity="0" group="1" density="0" rgba="0.7 0.7 0.7 1" mesh="right_wrist_pitch_link"/>
                        <body name="arm_r7_link" pos="0.046 0 0" gravcomp="0">
                          <inertial pos="0.0708244 -0.000191745 0.00161742" quat="0.493188 0.468078 0.526295 0.510571" mass="0.254576" diaginertia="0.000646113 0.000559993 0.000147566"/>
                          <joint name="arm_r7_joint" pos="0 0 0" axis="0 0 1" range="-1.61443 1.61443"/>
                          <geom type="mesh" contype="0" conaffinity="0" group="1" density="0" rgba="0.7 0.7 0.7 1" mesh="right_wrist_yaw_link"/>
                          <geom pos="0.0415 -0.003 0" type="mesh" contype="0" conaffinity="0" group="1" density="0" rgba="0.7 0.7 0.7 1" mesh="right_rubber_hand"/>
                          <!-- right hand collision -->
                          <geom name="right_hand_collision" type="capsule" size="0.05" fromto="0.05 0 0 0.1 0 0" contype="1" conaffinity="1" rgba="0 0 0 0"/>
                        </body>
                      </body>
                    </body>
                  </body>
                </body>
              </body>
            </body>
          </body>
        </body>
      </body>
    </body>
  </worldbody>
  <option timestep="0.001"/>
  <actuator>
    <motor name="leg_l1_joint" joint="leg_l1_joint" ctrlrange="-880.0 880.0"/>
    <motor name="leg_l2_joint" joint="leg_l2_joint" ctrlrange="-1390.0 1390.0"/>
    <motor name="leg_l3_joint" joint="leg_l3_joint" ctrlrange="-880.0 880.0"/>
    <motor name="leg_l4_joint" joint="leg_l4_joint" ctrlrange="-1390.0 1390.0"/>
    <motor name="leg_l5_joint" joint="leg_l5_joint" ctrlrange="-500.0 500.0"/>
    <motor name="leg_l6_joint" joint="leg_l6_joint" ctrlrange="-500.0 500.0"/>
    <motor name="leg_r1_joint" joint="leg_r1_joint" ctrlrange="-880.0 880.0"/>
    <motor name="leg_r2_joint" joint="leg_r2_joint" ctrlrange="-1390.0 1390.0"/>
    <motor name="leg_r3_joint" joint="leg_r3_joint" ctrlrange="-880.0 880.0"/>
    <motor name="leg_r4_joint" joint="leg_r4_joint" ctrlrange="-1390.0 1390.0"/>
    <motor name="leg_r5_joint" joint="leg_r5_joint" ctrlrange="-500.0 500.0"/>
    <motor name="leg_r6_joint" joint="leg_r6_joint" ctrlrange="-500.0 500.0"/>
    <motor name="waist_yaw_joint" joint="waist_yaw_joint" ctrlrange="-880.0 880.0"/>
    <motor name="waist_roll_joint" joint="waist_roll_joint" ctrlrange="-500.0 500.0"/>
    <motor name="waist_pitch_joint" joint="waist_pitch_joint" ctrlrange="-500.0 500.0"/>
    <motor name="arm_l1_joint" joint="arm_l1_joint" ctrlrange="-250.0 250.0"/>
    <motor name="arm_l2_joint" joint="arm_l2_joint" ctrlrange="-250.0 250.0"/>
    <motor name="arm_l3_joint" joint="arm_l3_joint" ctrlrange="-250.0 250.0"/>
    <motor name="arm_l4_joint" joint="arm_l4_joint" ctrlrange="-250.0 250.0"/>
    <motor name="arm_l5_joint" joint="arm_l5_joint" ctrlrange="-250.0 250.0"/>
    <motor name="arm_l6_joint" joint="arm_l6_joint" ctrlrange="-50.0 50.0"/>
    <motor name="arm_l7_joint" joint="arm_l7_joint" ctrlrange="-50.0 50.0"/>
    <motor name="arm_r1_joint" joint="arm_r1_joint" ctrlrange="-250.0 250.0"/>
    <motor name="arm_r2_joint" joint="arm_r2_joint" ctrlrange="-250.0 250.0"/>
    <motor name="arm_r3_joint" joint="arm_r3_joint" ctrlrange="-250.0 250.0"/>
    <motor name="arm_r4_joint" joint="arm_r4_joint" ctrlrange="-250.0 250.0"/>
    <motor name="arm_r5_joint" joint="arm_r5_joint" ctrlrange="-250.0 250.0"/>
    <motor name="arm_r6_joint" joint="arm_r6_joint" ctrlrange="-50.0 50.0"/>
    <motor name="arm_r7_joint" joint="arm_r7_joint" ctrlrange="-50.0 50.0"/>
  </actuator>
</mujoco>
